Workbook

Sheet All_India_Index_Upto_April23 (1
A1: Sector | B1: Year | C1: Month | D1: Cereals and products | E1: Meat and fish | F1: Egg | G1: Milk and products | H1: Oils and fats | I1: Fruits | J1: Vegetables | K1: Pulses and products | L1: Sugar and Confectionery | M1: Spices | N1: Non-alcoholic beverages | O1: Prepared meals, snacks, sweets etc. | P1: Food and beverages | Q1: Pan, tobacco and intoxicants | R1: Clothing | S1: Footwear | T1: Clothing and footwear | U1: Housing | V1: Fuel and light | W1: Household goods and services | X1: Health | Y1: Transport and communication | Z1: Recreation and amusement | AA1: Education | AB1: Personal care and effects | AC1: Miscellaneous | AD1: General index
A2: Rural | B2: 2013 | C2: January | D2: 107.5 | E2: 106.3 | F2: 108.1 | G2: 104.9 | H2: 106.1 | I2: 103.9 | J2: 101.9 | K2: 106.1 | L2: 106.8 | M2: 103.1 | N2: 104.8 | O2: 106.7 | P2: 105.5 | Q2: 105.1 | R2: 106.5 | S2: 105.8 | T2: 106.4 | U2: NA | V2: 105.5 | W2: 104.8 | X2: 104 | Y2: 103.3 | Z2: 103.4 | AA2: 103.8 | AB2: 104.7 | AC2: 104 | AD2: 105.1
A3: Urban | B3: 2013 | C3: January | D3: 110.5 | E3: 109.1 | F3: 113 | G3: 103.6 | H3: 103.4 | I3: 102.3 | J3: 102.9 | K3: 105.8 | L3: 105.1 | M3: 101.8 | N3: 105.1 | O3: 107.9 | P3: 105.9 | Q3: 105.2 | R3: 105.9 | S3: 105 | T3: 105.8 | U3: 100.3 | V3: 105.4 | W3: 104.8 | X3: 104.1 | Y3: 103.2 | Z3: 102.9 | AA3: 103.5 | AB3: 104.3 | AC3: 103.7 | AD3: 104
A4: Rural+Urban | B4: 2013 | C4: January | D4: 108.4 | E4: 107.3 | F4: 110 | G4: 104.4 | H4: 105.1 | I4: 103.2 | J4: 102.2 | K4: 106 | L4: 106.2 | M4: 102.7 | N4: 104.9 | O4: 107.3 | P4: 105.6 | Q4: 105.1 | R4: 106.3 | S4: 105.5 | T4: 106.2 | U4: 100.3 | V4: 105.5 | W4: 104.8 | X4: 104 | Y4: 103.2 | Z4: 103.1 | AA4: 103.6 | AB4: 104.5 | AC4: 103.9 | AD4: 104.6
A5: Rural | B5: 2013 | C5: February | D5: 109.2 | E5: 108.7 | F5: 110.2 | G5: 105.4 | H5: 106.7 | I5: 104 | J5: 102.4 | K5: 105.9 | L5: 105.7 | M5: 103.1 | N5: 105.1 | O5: 107.7 | P5: 106.3 | Q5: 105.6 | R5: 107.1 | S5: 106.3 | T5: 107 | U5: NA | V5: 106.2 | W5: 105.2 | X5: 104.4 | Y5: 103.9 | Z5: 104 | AA5: 104.1 | AB5: 104.6 | AC5: 104.4 | AD5: 105.8
A6: Urban | B6: 2013 | C6: February | D6: 112.9 | E6: 112.9 | F6: 116.9 | G6: 104 | H6: 103.5 | I6: 103.1 | J6: 104.9 | K6: 104.1 | L6: 103.8 | M6: 102.3 | N6: 106 | O6: 109 | P6: 107.2 | Q6: 106 | R6: 106.6 | S6: 105.5 | T6: 106.4 | U6: 100.4 | V6: 105.7 | W6: 105.2 | X6: 104.7 | Y6: 104.4 | Z6: 103.3 | AA6: 103.7 | AB6: 104.3 | AC6: 104.3 | AD6: 104.7
A7: Rural+Urban | B7: 2013 | C7: February | D7: 110.4 | E7: 110.2 | F7: 112.8 | G7: 104.9 | H7: 105.5 | I7: 103.6 | J7: 103.2 | K7: 105.3 | L7: 105.1 | M7: 102.8 | N7: 105.5 | O7: 108.3 | P7: 106.6 | Q7: 105.7 | R7: 106.9 | S7: 106 | T7: 106.8 | U7: 100.4 | V7: 106 | W7: 105.2 | X7: 104.5 | Y7: 104.2 | Z7: 103.6 | AA7: 103.9 | AB7: 104.5 | AC7: 104.4 | AD7: 105.3
A8: Rural | B8: 2013 | C8: March | D8: 110.2 | E8: 108.8 | F8: 109.9 | G8: 105.6 | H8: 106.2 | I8: 105.7 | J8: 101.4 | K8: 105.7 | L8: 105 | M8: 103.3 | N8: 105.6 | O8: 108.2 | P8: 106.6 | Q8: 106.5 | R8: 107.6 | S8: 106.8 | T8: 107.5 | U8: NA | V8: 106.1 | W8: 105.6 | X8: 104.7 | Y8: 104.6 | Z8: 104 | AA8: 104.3 | AB8: 104.3 | AC8: 104.6 | AD8: 106
A9: Urban | B9: 2013 | C9: March | D9: 113.9 | E9: 111.4 | F9: 113.2 | G9: 104.3 | H9: 102.7 | I9: 104.9 | J9: 103.8 | K9: 103.5 | L9: 102.6 | M9: 102.4 | N9: 107 | O9: 109.8 | P9: 107.3 | Q9: 106.8 | R9: 107.2 | S9: 106 | T9: 107 | U9: 100.4 | V9: 106 | W9: 105.7 | X9: 105.2 | Y9: 105.5 | Z9: 103.5 | AA9: 103.8 | AB9: 104.2 | AC9: 104.9 | AD9: 105
A10: Rural+Urban | B10: 2013 | C10: March | D10: 111.4 | E10: 109.7 | F10: 111.2 | G10: 105.1 | H10: 104.9 | I10: 105.3 | J10: 102.2 | K10: 105 | L10: 104.2 | M10: 103 | N10: 106.2 | O10: 108.9 | P10: 106.9 | Q10: 106.6 | R10: 107.4 | S10: 106.5 | T10: 107.3 | U10: 100.4 | V10: 106.1 | W10: 105.6 | X10: 104.9 | Y10: 105.1 | Z10: 103.7 | AA10: 104 | AB10: 104.3 | AC10: 104.7 | AD10: 105.5
A11: Rural | B11: 2013 | C11: April | D11: 110.2 | E11: 109.5 | F11: 106.9 | G11: 106.3 | H11: 105.7 | I11: 108.3 | J11: 103.4 | K11: 105.7 | L11: 104.2 | M11: 103.2 | N11: 106.5 | O11: 108.8 | P11: 107.1 | Q11: 107.1 | R11: 108.1 | S11: 107.4 | T11: 108 | U11: NA | V11: 106.5 | W11: 106.1 | X11: 105.1 | Y11: 104.4 | Z11: 104.5 | AA11: 104.8 | AB11: 102.7 | AC11: 104.6 | AD11: 106.4
A12: Urban | B12: 2013 | C12: April | D12: 114.6 | E12: 113.4 | F12: 106 | G12: 104.7 | H12: 102.1 | I12: 109.5 | J12: 109.7 | K12: 104.6 | L12: 102 | M12: 103.5 | N12: 108.2 | O12: 110.6 | P12: 108.8 | Q12: 108.5 | R12: 107.9 | S12: 106.4 | T12: 107.7 | U12: 100.5 | V12: 106.4 | W12: 106.5 | X12: 105.7 | Y12: 105 | Z12: 104 | AA12: 105.2 | AB12: 103.2 | AC12: 105.1 | AD12: 105.7
A13: Rural+Urban | B13: 2013 | C13: April | D13: 111.6 | E13: 110.9 | F13: 106.6 | G13: 105.7 | H13: 104.4 | I13: 108.9 | J13: 105.5 | K13: 105.3 | L13: 103.5 | M13: 103.3 | N13: 107.2 | O13: 109.6 | P13: 107.7 | Q13: 107.5 | R13: 108 | S13: 107 | T13: 107.9 | U13: 100.5 | V13: 106.5 | W13: 106.3 | X13: 105.3 | Y13: 104.7 | Z13: 104.2 | AA13: 105 | AB13: 102.9 | AC13: 104.8 | AD13: 106.1
A14: Rural | B14: 2013 | C14: May | D14: 110.9 | E14: 109.8 | F14: 105.9 | G14: 107.5 | H14: 105.3 | I14: 108.1 | J14: 107.3 | K14: 106.1 | L14: 103.7 | M14: 104 | N14: 107.4 | O14: 109.9 | P14: 108.1 | Q14: 108.1 | R14: 108.8 | S14: 107.9 | T14: 108.6 | U14: NA | V14: 107.5 | W14: 106.8 | X14: 105.7 | Y14: 104.1 | Z14: 105 | AA14: 105.5 | AB14: 102.1 | AC14: 104.8 | AD14: 107.2
A15: Urban | B15: 2013 | C15: May | D15: 115.4 | E15: 114.2 | F15: 102.7 | G15: 105.5 | H15: 101.5 | I15: 110.6 | J15: 123.7 | K15: 105.2 | L15: 101.9 | M15: 105 | N15: 109.1 | O15: 111.3 | P15: 111.1 | Q15: 109.8 | R15: 108.5 | S15: 106.7 | T15: 108.3 | U15: 100.5 | V15: 107.2 | W15: 107.1 | X15: 106.2 | Y15: 103.9 | Z15: 104.6 | AA15: 105.7 | AB15: 102.6 | AC15: 104.9 | AD15: 106.6
A16: Rural+Urban | B16: 2013 | C16: May | D16: 112.3 | E16: 111.3 | F16: 104.7 | G16: 106.8 | H16: 103.9 | I16: 109.3 | J16: 112.9 | K16: 105.8 | L16: 103.1 | M16: 104.3 | N16: 108.1 | O16: 110.5 | P16: 109.2 | Q16: 108.6 | R16: 108.7 | S16: 107.4 | T16: 108.5 | U16: 100.5 | V16: 107.4 | W16: 106.9 | X16: 105.9 | Y16: 104 | Z16: 104.8 | AA16: 105.6 | AB16: 102.3 | AC16: 104.8 | AD16: 106.9
A17: Rural | B17: 2013 | C17: June | D17: 112.3 | E17: 112.1 | F17: 108.1 | G17: 108.3 | H17: 105.9 | I17: 109.2 | J17: 118 | K17: 106.8 | L17: 104.1 | M17: 105.4 | N17: 108.2 | O17: 111 | P17: 110.6 | Q17: 109 | R17: 109.7 | S17: 108.8 | T17: 109.5 | U17: NA | V17: 108.5 | W17: 107.5 | X17: 106.3 | Y17: 105 | Z17: 105.6 | AA17: 106.5 | AB17: 102.5 | AC17: 105.5 | AD17: 108.9
A18: Urban | B18: 2013 | C18: June | D18: 117 | E18: 120.1 | F18: 112.5 | G18: 107.3 | H18: 101.3 | I18: 112.4 | J18: 143.6 | K18: 105.4 | L18: 101.4 | M18: 106.4 | N18: 110 | O18: 112.2 | P18: 115 | Q18: 110.9 | R18: 109.2 | S18: 107.2 | T18: 108.9 | U18: 106.6 | V18: 108 | W18: 107.7 | X18: 106.5 | Y18: 105.2 | Z18: 105.2 | AA18: 108.1 | AB18: 103.3 | AC18: 106.1 | AD18: 109.7
A19: Rural+Urban | B19: 2013 | C19: June | D19: 113.8 | E19: 114.9 | F19: 109.8 | G19: 107.9 | H19: 104.2 | I19: 110.7 | J19: 126.7 | K19: 106.3 | L19: 103.2 | M19: 105.7 | N19: 109 | O19: 111.6 | P19: 112.2 | Q19: 109.5 | R19: 109.5 | S19: 108.1 | T19: 109.3 | U19: 106.6 | V19: 108.3 | W19: 107.6 | X19: 106.4 | Y19: 105.1 | Z19: 105.4 | AA19: 107.4 | AB19: 102.8 | AC19: 105.8 | AD19: 109.3
A20: Rural | B20: 2013 | C20: July | D20: 113.4 | E20: 114.9 | F20: 110.5 | G20: 109.3 | H20: 106.2 | I20: 110.3 | J20: 129.2 | K20: 107.1 | L20: 104.3 | M20: 106.4 | N20: 109.1 | O20: 112.1 | P20: 113.1 | Q20: 109.8 | R20: 110.5 | S20: 109.5 | T20: 110.3 | U20: NA | V20: 109.5 | W20: 108.3 | X20: 106.9 | Y20: 106.8 | Z20: 106.4 | AA20: 107.8 | AB20: 102.5 | AC20: 106.5 | AD20: 110.7
A21: Urban | B21: 2013 | C21: July | D21: 117.8 | E21: 119.2 | F21: 114 | G21: 108.3 | H21: 101.1 | I21: 113.2 | J21: 160.9 | K21: 105.1 | L21: 101.3 | M21: 107.5 | N21: 110.4 | O21: 113.1 | P21: 117.5 | Q21: 111.7 | R21: 109.8 | S21: 107.8 | T21: 109.5 | U21: 107.7 | V21: 108.6 | W21: 108.1 | X21: 107.1 | Y21: 107.3 | Z21: 105.9 | AA21: 110.1 | AB21: 103.2 | AC21: 107.3 | AD21: 111.4
A22: Rural+Urban | B22: 2013 | C22: July | D22: 114.8 | E22: 116.4 | F22: 111.9 | G22: 108.9 | H22: 104.3 | I22: 111.7 | J22: 140 | K22: 106.4 | L22: 103.3 | M22: 106.8 | N22: 109.6 | O22: 112.6 | P22: 114.7 | Q22: 110.3 | R22: 110.2 | S22: 108.8 | T22: 110 | U22: 107.7 | V22: 109.2 | W22: 108.2 | X22: 107 | Y22: 107.1 | Z22: 106.1 | AA22: 109.1 | AB22: 102.8 | AC22: 106.9 | AD22: 111
A23: Rural | B23: 2013 | C23: August | D23: 114.3 | E23: 115.4 | F23: 111.1 | G23: 110 | H23: 106.4 | I23: 110.8 | J23: 138.9 | K23: 107.4 | L23: 104.1 | M23: 106.9 | N23: 109.7 | O23: 112.6 | P23: 114.9 | Q23: 110.7 | R23: 111.3 | S23: 110.2 | T23: 111.1 | U23: NA | V23: 109.9 | W23: 108.7 | X23: 107.5 | Y23: 107.8 | Z23: 106.8 | AA23: 108.7 | AB23: 105 | AC23: 107.5 | AD23: 112.1
A24: Urban | B24: 2013 | C24: August | D24: 118.3 | E24: 120.4 | F24: 112.7 | G24: 108.9 | H24: 101.1 | I24: 108.7 | J24: 177 | K24: 104.7 | L24: 101 | M24: 108.5 | N24: 110.9 | O24: 114.3 | P24: 119.6 | Q24: 112.4 | R24: 110.6 | S24: 108.3 | T24: 110.2 | U24: 108.9 | V24: 109.3 | W24: 108.7 | X24: 107.6 | Y24: 108.1 | Z24: 106.5 | AA24: 110.8 | AB24: 106 | AC24: 108.3 | AD24: 112.7
A25: Rural+Urban | B25: 2013 | C25: August | D25: 115.6 | E25: 117.2 | F25: 111.7 | G25: 109.6 | H25: 104.5 | I25: 109.8 | J25: 151.8 | K25: 106.5 | L25: 103.1 | M25: 107.4 | N25: 110.2 | O25: 113.4 | P25: 116.6 | Q25: 111.2 | R25: 111 | S25: 109.4 | T25: 110.7 | U25: 108.9 | V25: 109.7 | W25: 108.7 | X25: 107.5 | Y25: 108 | Z25: 106.6 | AA25: 109.9 | AB25: 105.4 | AC25: 107.9 | AD25: 112.4
A26: Rural | B26: 2013 | C26: September | D26: 115.4 | E26: 115.7 | F26: 111.7 | G26: 111 | H26: 107.4 | I26: 110.9 | J26: 154 | K26: 108.1 | L26: 104.2 | M26: 107.9 | N26: 110.4 | O26: 114 | P26: 117.8 | Q26: 111.7 | R26: 112.7 | S26: 111.4 | T26: 112.5 | U26: NA | V26: 111.1 | W26: 109.6 | X26: 108.3 | Y26: 109.3 | Z26: 107.7 | AA26: 109.8 | AB26: 106.7 | AC26: 108.7 | AD26: 114.2
A27: Urban | B27: 2013 | C27: September | D27: 118.6 | E27: 119.1 | F27: 113.2 | G27: 109.6 | H27: 101.7 | I27: 103.2 | J27: 174.3 | K27: 105.1 | L27: 100.8 | M27: 109.1 | N27: 111.1 | O27: 115.4 | P27: 119.2 | Q27: 112.9 | R27: 111.4 | S27: 109 | T27: 111.1 | U27: 109.7 | V27: 109.5 | W27: 109.6 | X27: 107.9 | Y27: 110.4 | Z27: 107.4 | AA27: 111.2 | AB27: 106.9 | AC27: 109.4 | AD27: 113.2
A28: Rural+Urban | B28: 2013 | C28: September | D28: 116.4 | E28: 116.9 | F28: 112.3 | G28: 110.5 | H28: 105.3 | I28: 107.3 | J28: 160.9 | K28: 107.1 | L28: 103.1 | M28: 108.3 | N28: 110.7 | O28: 114.6 | P28: 118.3 | Q28: 112 | R28: 112.2 | S28: 110.4 | T28: 111.9 | U28: 109.7 | V28: 110.5 | W28: 109.6 | X28: 108.1 | Y28: 109.9 | Z28: 107.5 | AA28: 110.6 | AB28: 106.8 | AC28: 109 | AD28: 113.7
A29: Rural | B29: 2013 | C29: October | D29: 116.3 | E29: 115.4 | F29: 112.6 | G29: 111.7 | H29: 107.7 | I29: 113.2 | J29: 164.9 | K29: 108.3 | L29: 103.9 | M29: 108.2 | N29: 111.1 | O29: 114.9 | P29: 119.8 | Q29: 112.2 | R29: 113.6 | S29: 112.3 | T29: 113.4 | U29: NA | V29: 111.6 | W29: 110.4 | X29: 108.9 | Y29: 109.3 | Z29: 108.3 | AA29: 110.2 | AB29: 107.5 | AC29: 109.1 | AD29: 115.5
A30: Urban | B30: 2013 | C30: October | D30: 118.9 | E30: 118.1 | F30: 114.5 | G30: 110.4 | H30: 102.3 | I30: 106.2 | J30: 183.5 | K30: 105.3 | L30: 100.2 | M30: 109.6 | N30: 111.4 | O30: 116 | P30: 120.8 | Q30: 113.5 | R30: 112.5 | S30: 109.7 | T30: 112 | U30: 110.5 | V30: 109.7 | W30: 110.2 | X30: 108.2 | Y30: 109.7 | Z30: 108 | AA30: 111.3 | AB30: 107.3 | AC30: 109.4 | AD30: 114
A31: Rural+Urban | B31: 2013 | C31: October | D31: 117.1 | E31: 116.3 | F31: 113.3 | G31: 111.2 | H31: 105.7 | I31: 109.9 | J31: 171.2 | K31: 107.3 | L31: 102.7 | M31: 108.7 | N31: 111.2 | O31: 115.4 | P31: 120.2 | Q31: 112.5 | R31: 113.2 | S31: 111.2 | T31: 112.8 | U31: 110.5 | V31: 110.9 | W31: 110.3 | X31: 108.6 | Y31: 109.5 | Z31: 108.1 | AA31: 110.8 | AB31: 107.4 | AC31: 109.2 | AD31: 114.8
A32: Rural | B32: 2013 | C32: November | D32: 117.3 | E32: 114.9 | F32: 116.2 | G32: 112.8 | H32: 108.9 | I32: 116.6 | J32: 178.1 | K32: 109.1 | L32: 103.6 | M32: 109 | N32: 111.8 | O32: 116 | P32: 122.5 | Q32: 112.8 | R32: 114.6 | S32: 113.1 | T32: 114.4 | U32: NA | V32: 112.6 | W32: 111.3 | X32: 109.7 | Y32: 109.6 | Z32: 108.7 | AA32: 111 | AB32: 108.2 | AC32: 109.8 | AD32: 117.4
A33: Urban | B33: 2013 | C33: November | D33: 119.8 | E33: 116.3 | F33: 122.6 | G33: 112 | H33: 103.2 | I33: 110 | J33: 192.8 | K33: 106.3 | L33: 99.5 | M33: 110.3 | N33: 111.8 | O33: 117.1 | P33: 122.9 | Q33: 114.1 | R33: 113.5 | S33: 110.3 | T33: 113 | U33: 111.1 | V33: 110 | W33: 110.9 | X33: 108.6 | Y33: 109.5 | Z33: 108.5 | AA33: 111.3 | AB33: 107.9 | AC33: 109.6 | AD33: 115
A34: Rural+Urban | B34: 2013 | C34: November | D34: 118.1 | E34: 115.4 | F34: 118.7 | G34: 112.5 | H34: 106.8 | I34: 113.5 | J34: 183.1 | K34: 108.2 | L34: 102.2 | M34: 109.4 | N34: 111.8 | O34: 116.5 | P34: 122.6 | Q34: 113.1 | R34: 114.2 | S34: 111.9 | T34: 113.8 | U34: 111.1 | V34: 111.6 | W34: 111.1 | X34: 109.3 | Y34: 109.5 | Z34: 108.6 | AA34: 111.2 | AB34: 108.1 | AC34: 109.7 | AD34: 116.3
A35: Rural | B35: 2013 | C35: December | D35: 118.4 | E35: 115.9 | F35: 120.4 | G35: 113.8 | H35: 109.5 | I35: 115.5 | J35: 145.7 | K35: 109.5 | L35: 102.9 | M35: 109.8 | N35: 112.1 | O35: 116.8 | P35: 118.7 | Q35: 113.6 | R35: 115.8 | S35: 114 | T35: 115.5 | U35: NA | V35: 112.8 | W35: 112.1 | X35: 110.1 | Y35: 109.9 | Z35: 109.2 | AA35: 111.6 | AB35: 108.1 | AC35: 110.1 | AD35: 115.5
A36: Urban | B36: 2013 | C36: December | D36: 120.5 | E36: 118.1 | F36: 128.5 | G36: 112.8 | H36: 103.4 | I36: 110.7 | J36: 144.8 | K36: 107.1 | L36: 98.6 | M36: 111.9 | N36: 112.1 | O36: 118.1 | P36: 117.8 | Q36: 115 | R36: 114.2 | S36: 110.9 | T36: 113.7 | U36: 110.7 | V36: 110.4 | W36: 111.3 | X36: 109 | Y36: 109.7 | Z36: 108.9 | AA36: 111.4 | AB36: 107.7 | AC36: 109.8 | AD36: 113.3
A37: Rural+Urban | B37: 2013 | C37: December | D37: 119.1 | E37: 116.7 | F37: 123.5 | G37: 113.4 | H37: 107.3 | I37: 113.3 | J37: 145.4 | K37: 108.7 | L37: 101.5 | M37: 110.5 | N37: 112.1 | O37: 117.4 | P37: 118.4 | Q37: 114 | R37: 115.2 | S37: 112.7 | T37: 114.8 | U37: 110.7 | V37: 111.9 | W37: 111.7 | X37: 109.7 | Y37: 109.8 | Z37: 109 | AA37: 111.5 | AB37: 107.9 | AC37: 110 | AD37: 114.5
A38: Rural | B38: 2014 | C38: January | D38: 118.9 | E38: 117.1 | F38: 120.5 | G38: 114.4 | H38: 109 | I38: 115.5 | J38: 123.9 | K38: 109.6 | L38: 101.8 | M38: 110.2 | N38: 112.4 | O38: 117.3 | P38: 116 | Q38: 114 | R38: 116.5 | S38: 114.5 | T38: 116.2 | U38: NA | V38: 113 | W38: 112.6 | X38: 110.6 | Y38: 110.5 | Z38: 109.6 | AA38: 111.8 | AB38: 108.3 | AC38: 110.6 | AD38: 114.2
A39: Urban | B39: 2014 | C39: January | D39: 121.2 | E39: 122 | F39: 129.9 | G39: 113.6 | H39: 102.9 | I39: 112.1 | J39: 118.9 | K39: 107.5 | L39: 96.9 | M39: 112.7 | N39: 112.1 | O39: 119 | P39: 115.5 | Q39: 115.7 | R39: 114.8 | S39: 111.3 | T39: 114.3 | U39: 111.6 | V39: 111 | W39: 111.9 | X39: 109.7 | Y39: 110.8 | Z39: 109.8 | AA39: 111.5 | AB39: 108 | AC39: 110.5 | AD39: 112.9
A40: Rural+Urban | B40: 2014 | C40: January | D40: 119.6 | E40: 118.8 | F40: 124.1 | G40: 114.1 | H40: 106.8 | I40: 113.9 | J40: 122.2 | K40: 108.9 | L40: 100.2 | M40: 111 | N40: 112.3 | O40: 118.1 | P40: 115.8 | Q40: 114.5 | R40: 115.8 | S40: 113.2 | T40: 115.4 | U40: 111.6 | V40: 112.2 | W40: 112.3 | X40: 110.3 | Y40: 110.7 | Z40: 109.7 | AA40: 111.6 | AB40: 108.2 | AC40: 110.6 | AD40: 113.6
...

Sheet Cleaned data
A1: Sector | B1: Year | C1: Month | D1: Cereals and products | E1: Meat and fish | F1: Egg | G1: Milk and products | H1: Oils and fats | I1: Fruits | J1: Vegetables | K1: Pulses and products | L1: Sugar and Confectionery | M1: Spices | N1: Non-alcoholic beverages | O1: Prepared meals, snacks, sweets etc. | P1: Food and beverages | Q1: Pan, tobacco and intoxicants | R1: Clothing | S1: Footwear | T1: Clothing and footwear | U1: Housing | V1: Fuel and light | W1: Household goods and services | X1: Health | Y1: Transport and communication | Z1: Recreation and amusement | AA1: Education | AB1: Personal care and effects | AC1: Miscellaneous | AD1: General index
A2: Rural | B2: 2013 | C2: January | D2: 107.5 | E2: 106.3 | F2: 108.1 | G2: 104.9 | H2: 106.1 | I2: 103.9 | J2: 101.9 | K2: 106.1 | L2: 106.8 | M2: 103.1 | N2: 104.8 | O2: 106.7 | P2: 105.5 | Q2: 105.1 | R2: 106.5 | S2: 105.8 | T2: 106.4 | U2: NA | V2: 105.5 | W2: 104.8 | X2: 104 | Y2: 103.3 | Z2: 103.4 | AA2: 103.8 | AB2: 104.7 | AC2: 104 | AD2: 105.1
A3: Urban | B3: 2013 | C3: January | D3: 110.5 | E3: 109.1 | F3: 113 | G3: 103.6 | H3: 103.4 | I3: 102.3 | J3: 102.9 | K3: 105.8 | L3: 105.1 | M3: 101.8 | N3: 105.1 | O3: 107.9 | P3: 105.9 | Q3: 105.2 | R3: 105.9 | S3: 105 | T3: 105.8 | U3: 100.3 | V3: 105.4 | W3: 104.8 | X3: 104.1 | Y3: 103.2 | Z3: 102.9 | AA3: 103.5 | AB3: 104.3 | AC3: 103.7 | AD3: 104
A4: Rural+Urban | B4: 2013 | C4: January | D4: 108.4 | E4: 107.3 | F4: 110 | G4: 104.4 | H4: 105.1 | I4: 103.2 | J4: 102.2 | K4: 106 | L4: 106.2 | M4: 102.7 | N4: 104.9 | O4: 107.3 | P4: 105.6 | Q4: 105.1 | R4: 106.3 | S4: 105.5 | T4: 106.2 | U4: 100.3 | V4: 105.5 | W4: 104.8 | X4: 104 | Y4: 103.2 | Z4: 103.1 | AA4: 103.6 | AB4: 104.5 | AC4: 103.9 | AD4: 104.6
A5: Rural | B5: 2013 | C5: February | D5: 109.2 | E5: 108.7 | F5: 110.2 | G5: 105.4 | H5: 106.7 | I5: 104 | J5: 102.4 | K5: 105.9 | L5: 105.7 | M5: 103.1 | N5: 105.1 | O5: 107.7 | P5: 106.3 | Q5: 105.6 | R5: 107.1 | S5: 106.3 | T5: 107 | U5: NA | V5: 106.2 | W5: 105.2 | X5: 104.4 | Y5: 103.9 | Z5: 104 | AA5: 104.1 | AB5: 104.6 | AC5: 104.4 | AD5: 105.8
A6: Urban | B6: 2013 | C6: February | D6: 112.9 | E6: 112.9 | F6: 116.9 | G6: 104 | H6: 103.5 | I6: 103.1 | J6: 104.9 | K6: 104.1 | L6: 103.8 | M6: 102.3 | N6: 106 | O6: 109 | P6: 107.2 | Q6: 106 | R6: 106.6 | S6: 105.5 | T6: 106.4 | U6: 100.4 | V6: 105.7 | W6: 105.2 | X6: 104.7 | Y6: 104.4 | Z6: 103.3 | AA6: 103.7 | AB6: 104.3 | AC6: 104.3 | AD6: 104.7
A7: Rural+Urban | B7: 2013 | C7: February | D7: 110.4 | E7: 110.2 | F7: 112.8 | G7: 104.9 | H7: 105.5 | I7: 103.6 | J7: 103.2 | K7: 105.3 | L7: 105.1 | M7: 102.8 | N7: 105.5 | O7: 108.3 | P7: 106.6 | Q7: 105.7 | R7: 106.9 | S7: 106 | T7: 106.8 | U7: 100.4 | V7: 106 | W7: 105.2 | X7: 104.5 | Y7: 104.2 | Z7: 103.6 | AA7: 103.9 | AB7: 104.5 | AC7: 104.4 | AD7: 105.3
A8: Rural | B8: 2013 | C8: March | D8: 110.2 | E8: 108.8 | F8: 109.9 | G8: 105.6 | H8: 106.2 | I8: 105.7 | J8: 101.4 | K8: 105.7 | L8: 105 | M8: 103.3 | N8: 105.6 | O8: 108.2 | P8: 106.6 | Q8: 106.5 | R8: 107.6 | S8: 106.8 | T8: 107.5 | U8: NA | V8: 106.1 | W8: 105.6 | X8: 104.7 | Y8: 104.6 | Z8: 104 | AA8: 104.3 | AB8: 104.3 | AC8: 104.6 | AD8: 106
A9: Urban | B9: 2013 | C9: March | D9: 113.9 | E9: 111.4 | F9: 113.2 | G9: 104.3 | H9: 102.7 | I9: 104.9 | J9: 103.8 | K9: 103.5 | L9: 102.6 | M9: 102.4 | N9: 107 | O9: 109.8 | P9: 107.3 | Q9: 106.8 | R9: 107.2 | S9: 106 | T9: 107 | U9: 100.4 | V9: 106 | W9: 105.7 | X9: 105.2 | Y9: 105.5 | Z9: 103.5 | AA9: 103.8 | AB9: 104.2 | AC9: 104.9 | AD9: 105
A10: Rural+Urban | B10: 2013 | C10: March | D10: 111.4 | E10: 109.7 | F10: 111.2 | G10: 105.1 | H10: 104.9 | I10: 105.3 | J10: 102.2 | K10: 105 | L10: 104.2 | M10: 103 | N10: 106.2 | O10: 108.9 | P10: 106.9 | Q10: 106.6 | R10: 107.4 | S10: 106.5 | T10: 107.3 | U10: 100.4 | V10: 106.1 | W10: 105.6 | X10: 104.9 | Y10: 105.1 | Z10: 103.7 | AA10: 104 | AB10: 104.3 | AC10: 104.7 | AD10: 105.5
A11: Rural | B11: 2013 | C11: April | D11: 110.2 | E11: 109.5 | F11: 106.9 | G11: 106.3 | H11: 105.7 | I11: 108.3 | J11: 103.4 | K11: 105.7 | L11: 104.2 | M11: 103.2 | N11: 106.5 | O11: 108.8 | P11: 107.1 | Q11: 107.1 | R11: 108.1 | S11: 107.4 | T11: 108 | U11: NA | V11: 106.5 | W11: 106.1 | X11: 105.1 | Y11: 104.4 | Z11: 104.5 | AA11: 104.8 | AB11: 102.7 | AC11: 104.6 | AD11: 106.4
A12: Urban | B12: 2013 | C12: April | D12: 114.6 | E12: 113.4 | F12: 106 | G12: 104.7 | H12: 102.1 | I12: 109.5 | J12: 109.7 | K12: 104.6 | L12: 102 | M12: 103.5 | N12: 108.2 | O12: 110.6 | P12: 108.8 | Q12: 108.5 | R12: 107.9 | S12: 106.4 | T12: 107.7 | U12: 100.5 | V12: 106.4 | W12: 106.5 | X12: 105.7 | Y12: 105 | Z12: 104 | AA12: 105.2 | AB12: 103.2 | AC12: 105.1 | AD12: 105.7
A13: Rural+Urban | B13: 2013 | C13: April | D13: 111.6 | E13: 110.9 | F13: 106.6 | G13: 105.7 | H13: 104.4 | I13: 108.9 | J13: 105.5 | K13: 105.3 | L13: 103.5 | M13: 103.3 | N13: 107.2 | O13: 109.6 | P13: 107.7 | Q13: 107.5 | R13: 108 | S13: 107 | T13: 107.9 | U13: 100.5 | V13: 106.5 | W13: 106.3 | X13: 105.3 | Y13: 104.7 | Z13: 104.2 | AA13: 105 | AB13: 102.9 | AC13: 104.8 | AD13: 106.1 | AM13: =COUNTIF($C:$C,"June") -> 30
A14: Rural | B14: 2013 | C14: May | D14: 110.9 | E14: 109.8 | F14: 105.9 | G14: 107.5 | H14: 105.3 | I14: 108.1 | J14: 107.3 | K14: 106.1 | L14: 103.7 | M14: 104 | N14: 107.4 | O14: 109.9 | P14: 108.1 | Q14: 108.1 | R14: 108.8 | S14: 107.9 | T14: 108.6 | U14: NA | V14: 107.5 | W14: 106.8 | X14: 105.7 | Y14: 104.1 | Z14: 105 | AA14: 105.5 | AB14: 102.1 | AC14: 104.8 | AD14: 107.2
A15: Urban | B15: 2013 | C15: May | D15: 115.4 | E15: 114.2 | F15: 102.7 | G15: 105.5 | H15: 101.5 | I15: 110.6 | J15: 123.7 | K15: 105.2 | L15: 101.9 | M15: 105 | N15: 109.1 | O15: 111.3 | P15: 111.1 | Q15: 109.8 | R15: 108.5 | S15: 106.7 | T15: 108.3 | U15: 100.5 | V15: 107.2 | W15: 107.1 | X15: 106.2 | Y15: 103.9 | Z15: 104.6 | AA15: 105.7 | AB15: 102.6 | AC15: 104.9 | AD15: 106.6 | AM15: =COUNTIFS($A:$A,"Rural+Urban",$C:$C,"June",$B:$B,2022) -> 1
A16: Rural+Urban | B16: 2013 | C16: May | D16: 112.3 | E16: 111.3 | F16: 104.7 | G16: 106.8 | H16: 103.9 | I16: 109.3 | J16: 112.9 | K16: 105.8 | L16: 103.1 | M16: 104.3 | N16: 108.1 | O16: 110.5 | P16: 109.2 | Q16: 108.6 | R16: 108.7 | S16: 107.4 | T16: 108.5 | U16: 100.5 | V16: 107.4 | W16: 106.9 | X16: 105.9 | Y16: 104 | Z16: 104.8 | AA16: 105.6 | AB16: 102.3 | AC16: 104.8 | AD16: 106.9
A17: Rural | B17: 2013 | C17: June | D17: 112.3 | E17: 112.1 | F17: 108.1 | G17: 108.3 | H17: 105.9 | I17: 109.2 | J17: 118 | K17: 106.8 | L17: 104.1 | M17: 105.4 | N17: 108.2 | O17: 111 | P17: 110.6 | Q17: 109 | R17: 109.7 | S17: 108.8 | T17: 109.5 | U17: NA | V17: 108.5 | W17: 107.5 | X17: 106.3 | Y17: 105 | Z17: 105.6 | AA17: 106.5 | AB17: 102.5 | AC17: 105.5 | AD17: 108.9
A18: Urban | B18: 2013 | C18: June | D18: 117 | E18: 120.1 | F18: 112.5 | G18: 107.3 | H18: 101.3 | I18: 112.4 | J18: 143.6 | K18: 105.4 | L18: 101.4 | M18: 106.4 | N18: 110 | O18: 112.2 | P18: 115 | Q18: 110.9 | R18: 109.2 | S18: 107.2 | T18: 108.9 | U18: 106.6 | V18: 108 | W18: 107.7 | X18: 106.5 | Y18: 105.2 | Z18: 105.2 | AA18: 108.1 | AB18: 103.3 | AC18: 106.1 | AD18: 109.7
A19: Rural+Urban | B19: 2013 | C19: June | D19: 113.8 | E19: 114.9 | F19: 109.8 | G19: 107.9 | H19: 104.2 | I19: 110.7 | J19: 126.7 | K19: 106.3 | L19: 103.2 | M19: 105.7 | N19: 109 | O19: 111.6 | P19: 112.2 | Q19: 109.5 | R19: 109.5 | S19: 108.1 | T19: 109.3 | U19: 106.6 | V19: 108.3 | W19: 107.6 | X19: 106.4 | Y19: 105.1 | Z19: 105.4 | AA19: 107.4 | AB19: 102.8 | AC19: 105.8 | AD19: 109.3
A20: Rural | B20: 2013 | C20: July | D20: 113.4 | E20: 114.9 | F20: 110.5 | G20: 109.3 | H20: 106.2 | I20: 110.3 | J20: 129.2 | K20: 107.1 | L20: 104.3 | M20: 106.4 | N20: 109.1 | O20: 112.1 | P20: 113.1 | Q20: 109.8 | R20: 110.5 | S20: 109.5 | T20: 110.3 | U20: NA | V20: 109.5 | W20: 108.3 | X20: 106.9 | Y20: 106.8 | Z20: 106.4 | AA20: 107.8 | AB20: 102.5 | AC20: 106.5 | AD20: 110.7
A21: Urban | B21: 2013 | C21: July | D21: 117.8 | E21: 119.2 | F21: 114 | G21: 108.3 | H21: 101.1 | I21: 113.2 | J21: 160.9 | K21: 105.1 | L21: 101.3 | M21: 107.5 | N21: 110.4 | O21: 113.1 | P21: 117.5 | Q21: 111.7 | R21: 109.8 | S21: 107.8 | T21: 109.5 | U21: 107.7 | V21: 108.6 | W21: 108.1 | X21: 107.1 | Y21: 107.3 | Z21: 105.9 | AA21: 110.1 | AB21: 103.2 | AC21: 107.3 | AD21: 111.4
A22: Rural+Urban | B22: 2013 | C22: July | D22: 114.8 | E22: 116.4 | F22: 111.9 | G22: 108.9 | H22: 104.3 | I22: 111.7 | J22: 140 | K22: 106.4 | L22: 103.3 | M22: 106.8 | N22: 109.6 | O22: 112.6 | P22: 114.7 | Q22: 110.3 | R22: 110.2 | S22: 108.8 | T22: 110 | U22: 107.7 | V22: 109.2 | W22: 108.2 | X22: 107 | Y22: 107.1 | Z22: 106.1 | AA22: 109.1 | AB22: 102.8 | AC22: 106.9 | AD22: 111
A23: Rural | B23: 2013 | C23: August | D23: 114.3 | E23: 115.4 | F23: 111.1 | G23: 110 | H23: 106.4 | I23: 110.8 | J23: 138.9 | K23: 107.4 | L23: 104.1 | M23: 106.9 | N23: 109.7 | O23: 112.6 | P23: 114.9 | Q23: 110.7 | R23: 111.3 | S23: 110.2 | T23: 111.1 | U23: NA | V23: 109.9 | W23: 108.7 | X23: 107.5 | Y23: 107.8 | Z23: 106.8 | AA23: 108.7 | AB23: 105 | AC23: 107.5 | AD23: 112.1
A24: Urban | B24: 2013 | C24: August | D24: 118.3 | E24: 120.4 | F24: 112.7 | G24: 108.9 | H24: 101.1 | I24: 108.7 | J24: 177 | K24: 104.7 | L24: 101 | M24: 108.5 | N24: 110.9 | O24: 114.3 | P24: 119.6 | Q24: 112.4 | R24: 110.6 | S24: 108.3 | T24: 110.2 | U24: 108.9 | V24: 109.3 | W24: 108.7 | X24: 107.6 | Y24: 108.1 | Z24: 106.5 | AA24: 110.8 | AB24: 106 | AC24: 108.3 | AD24: 112.7
A25: Rural+Urban | B25: 2013 | C25: August | D25: 115.6 | E25: 117.2 | F25: 111.7 | G25: 109.6 | H25: 104.5 | I25: 109.8 | J25: 151.8 | K25: 106.5 | L25: 103.1 | M25: 107.4 | N25: 110.2 | O25: 113.4 | P25: 116.6 | Q25: 111.2 | R25: 111 | S25: 109.4 | T25: 110.7 | U25: 108.9 | V25: 109.7 | W25: 108.7 | X25: 107.5 | Y25: 108 | Z25: 106.6 | AA25: 109.9 | AB25: 105.4 | AC25: 107.9 | AD25: 112.4
A26: Rural | B26: 2013 | C26: September | D26: 115.4 | E26: 115.7 | F26: 111.7 | G26: 111 | H26: 107.4 | I26: 110.9 | J26: 154 | K26: 108.1 | L26: 104.2 | M26: 107.9 | N26: 110.4 | O26: 114 | P26: 117.8 | Q26: 111.7 | R26: 112.7 | S26: 111.4 | T26: 112.5 | U26: NA | V26: 111.1 | W26: 109.6 | X26: 108.3 | Y26: 109.3 | Z26: 107.7 | AA26: 109.8 | AB26: 106.7 | AC26: 108.7 | AD26: 114.2
A27: Urban | B27: 2013 | C27: September | D27: 118.6 | E27: 119.1 | F27: 113.2 | G27: 109.6 | H27: 101.7 | I27: 103.2 | J27: 174.3 | K27: 105.1 | L27: 100.8 | M27: 109.1 | N27: 111.1 | O27: 115.4 | P27: 119.2 | Q27: 112.9 | R27: 111.4 | S27: 109 | T27: 111.1 | U27: 109.7 | V27: 109.5 | W27: 109.6 | X27: 107.9 | Y27: 110.4 | Z27: 107.4 | AA27: 111.2 | AB27: 106.9 | AC27: 109.4 | AD27: 113.2
A28: Rural+Urban | B28: 2013 | C28: September | D28: 116.4 | E28: 116.9 | F28: 112.3 | G28: 110.5 | H28: 105.3 | I28: 107.3 | J28: 160.9 | K28: 107.1 | L28: 103.1 | M28: 108.3 | N28: 110.7 | O28: 114.6 | P28: 118.3 | Q28: 112 | R28: 112.2 | S28: 110.4 | T28: 111.9 | U28: 109.7 | V28: 110.5 | W28: 109.6 | X28: 108.1 | Y28: 109.9 | Z28: 107.5 | AA28: 110.6 | AB28: 106.8 | AC28: 109 | AD28: 113.7
A29: Rural | B29: 2013 | C29: October | D29: 116.3 | E29: 115.4 | F29: 112.6 | G29: 111.7 | H29: 107.7 | I29: 113.2 | J29: 164.9 | K29: 108.3 | L29: 103.9 | M29: 108.2 | N29: 111.1 | O29: 114.9 | P29: 119.8 | Q29: 112.2 | R29: 113.6 | S29: 112.3 | T29: 113.4 | U29: NA | V29: 111.6 | W29: 110.4 | X29: 108.9 | Y29: 109.3 | Z29: 108.3 | AA29: 110.2 | AB29: 107.5 | AC29: 109.1 | AD29: 115.5
A30: Urban | B30: 2013 | C30: October | D30: 118.9 | E30: 118.1 | F30: 114.5 | G30: 110.4 | H30: 102.3 | I30: 106.2 | J30: 183.5 | K30: 105.3 | L30: 100.2 | M30: 109.6 | N30: 111.4 | O30: 116 | P30: 120.8 | Q30: 113.5 | R30: 112.5 | S30: 109.7 | T30: 112 | U30: 110.5 | V30: 109.7 | W30: 110.2 | X30: 108.2 | Y30: 109.7 | Z30: 108 | AA30: 111.3 | AB30: 107.3 | AC30: 109.4 | AD30: 114
A31: Rural+Urban | B31: 2013 | C31: October | D31: 117.1 | E31: 116.3 | F31: 113.3 | G31: 111.2 | H31: 105.7 | I31: 109.9 | J31: 171.2 | K31: 107.3 | L31: 102.7 | M31: 108.7 | N31: 111.2 | O31: 115.4 | P31: 120.2 | Q31: 112.5 | R31: 113.2 | S31: 111.2 | T31: 112.8 | U31: 110.5 | V31: 110.9 | W31: 110.3 | X31: 108.6 | Y31: 109.5 | Z31: 108.1 | AA31: 110.8 | AB31: 107.4 | AC31: 109.2 | AD31: 114.8
A32: Rural | B32: 2013 | C32: November | D32: 117.3 | E32: 114.9 | F32: 116.2 | G32: 112.8 | H32: 108.9 | I32: 116.6 | J32: 178.1 | K32: 109.1 | L32: 103.6 | M32: 109 | N32: 111.8 | O32: 116 | P32: 122.5 | Q32: 112.8 | R32: 114.6 | S32: 113.1 | T32: 114.4 | U32: NA | V32: 112.6 | W32: 111.3 | X32: 109.7 | Y32: 109.6 | Z32: 108.7 | AA32: 111 | AB32: 108.2 | AC32: 109.8 | AD32: 117.4
A33: Urban | B33: 2013 | C33: November | D33: 119.8 | E33: 116.3 | F33: 122.6 | G33: 112 | H33: 103.2 | I33: 110 | J33: 192.8 | K33: 106.3 | L33: 99.5 | M33: 110.3 | N33: 111.8 | O33: 117.1 | P33: 122.9 | Q33: 114.1 | R33: 113.5 | S33: 110.3 | T33: 113 | U33: 111.1 | V33: 110 | W33: 110.9 | X33: 108.6 | Y33: 109.5 | Z33: 108.5 | AA33: 111.3 | AB33: 107.9 | AC33: 109.6 | AD33: 115
A34: Rural+Urban | B34: 2013 | C34: November | D34: 118.1 | E34: 115.4 | F34: 118.7 | G34: 112.5 | H34: 106.8 | I34: 113.5 | J34: 183.1 | K34: 108.2 | L34: 102.2 | M34: 109.4 | N34: 111.8 | O34: 116.5 | P34: 122.6 | Q34: 113.1 | R34: 114.2 | S34: 111.9 | T34: 113.8 | U34: 111.1 | V34: 111.6 | W34: 111.1 | X34: 109.3 | Y34: 109.5 | Z34: 108.6 | AA34: 111.2 | AB34: 108.1 | AC34: 109.7 | AD34: 116.3
A35: Rural | B35: 2013 | C35: December | D35: 118.4 | E35: 115.9 | F35: 120.4 | G35: 113.8 | H35: 109.5 | I35: 115.5 | J35: 145.7 | K35: 109.5 | L35: 102.9 | M35: 109.8 | N35: 112.1 | O35: 116.8 | P35: 118.7 | Q35: 113.6 | R35: 115.8 | S35: 114 | T35: 115.5 | U35: NA | V35: 112.8 | W35: 112.1 | X35: 110.1 | Y35: 109.9 | Z35: 109.2 | AA35: 111.6 | AB35: 108.1 | AC35: 110.1 | AD35: 115.5
A36: Urban | B36: 2013 | C36: December | D36: 120.5 | E36: 118.1 | F36: 128.5 | G36: 112.8 | H36: 103.4 | I36: 110.7 | J36: 144.8 | K36: 107.1 | L36: 98.6 | M36: 111.9 | N36: 112.1 | O36: 118.1 | P36: 117.8 | Q36: 115 | R36: 114.2 | S36: 110.9 | T36: 113.7 | U36: 110.7 | V36: 110.4 | W36: 111.3 | X36: 109 | Y36: 109.7 | Z36: 108.9 | AA36: 111.4 | AB36: 107.7 | AC36: 109.8 | AD36: 113.3
A37: Rural+Urban | B37: 2013 | C37: December | D37: 119.1 | E37: 116.7 | F37: 123.5 | G37: 113.4 | H37: 107.3 | I37: 113.3 | J37: 145.4 | K37: 108.7 | L37: 101.5 | M37: 110.5 | N37: 112.1 | O37: 117.4 | P37: 118.4 | Q37: 114 | R37: 115.2 | S37: 112.7 | T37: 114.8 | U37: 110.7 | V37: 111.9 | W37: 111.7 | X37: 109.7 | Y37: 109.8 | Z37: 109 | AA37: 111.5 | AB37: 107.9 | AC37: 110 | AD37: 114.5
A38: Rural | B38: 2014 | C38: January | D38: 118.9 | E38: 117.1 | F38: 120.5 | G38: 114.4 | H38: 109 | I38: 115.5 | J38: 123.9 | K38: 109.6 | L38: 101.8 | M38: 110.2 | N38: 112.4 | O38: 117.3 | P38: 116 | Q38: 114 | R38: 116.5 | S38: 114.5 | T38: 116.2 | U38: NA | V38: 113 | W38: 112.6 | X38: 110.6 | Y38: 110.5 | Z38: 109.6 | AA38: 111.8 | AB38: 108.3 | AC38: 110.6 | AD38: 114.2
A39: Urban | B39: 2014 | C39: January | D39: 121.2 | E39: 122 | F39: 129.9 | G39: 113.6 | H39: 102.9 | I39: 112.1 | J39: 118.9 | K39: 107.5 | L39: 96.9 | M39: 112.7 | N39: 112.1 | O39: 119 | P39: 115.5 | Q39: 115.7 | R39: 114.8 | S39: 111.3 | T39: 114.3 | U39: 111.6 | V39: 111 | W39: 111.9 | X39: 109.7 | Y39: 110.8 | Z39: 109.8 | AA39: 111.5 | AB39: 108 | AC39: 110.5 | AD39: 112.9
A40: Rural+Urban | B40: 2014 | C40: January | D40: 119.6 | E40: 118.8 | F40: 124.1 | G40: 114.1 | H40: 106.8 | I40: 113.9 | J40: 122.2 | K40: 108.9 | L40: 100.2 | M40: 111 | N40: 112.3 | O40: 118.1 | P40: 115.8 | Q40: 114.5 | R40: 115.8 | S40: 113.2 | T40: 115.4 | U40: 111.6 | V40: 112.2 | W40: 112.3 | X40: 110.3 | Y40: 110.7 | Z40: 109.7 | AA40: 111.6 | AB40: 108.2 | AC40: 110.6 | AD40: 113.6
...

Sheet Category mapping
A1: Sub-Category | B1: Broader Bucket
A2: Cereals and products | B2: Food
A3: Meat and fish | B3: Food
A4: Egg | B4: Food
A5: Milk and products | B5: Food
A6: Oils and fats | B6: Food
A7: Fruits | B7: Food
A8: Vegetables | B8: Food
A9: Pulses and products | B9: Food
A10: Sugar and Confectionery | B10: Food
A11: Spices | B11: Food
A12: Non-alcoholic beverages | B12: Food
... A25: Miscellaneous | B25: Miscellaneous Services

Sheet broader category cont. Analysis
A1: Broader Category | B1: Sum of Index Values | C1: Contribution %
A2: Food | B2: =SUM('All_India_Index_Upto_April23 (1'!D373:O373) -> 2127.8 | C2: =B2/$B$8*100 -> 49.609475
A3: Pan Tobacco & Intoxicants | B3: =SUM('All_India_Index_Upto_April23 (1'!Q373) -> 201 | C3: =B3/$B$8*100 -> 4.6862978
A4: Clothing & Footwear | B4: =SUM('All_India_Index_Upto_April23 (1'!R373:S373) -> 367 | C4: =B4/$B$8*100 -> 8.5565736
A5: Housing | B5: =SUM('All_India_Index_Upto_April23 (1'!U373) -> 175.6 | C5: =B5/$B$8*100 -> 4.094099
A6: Fuel & Light | B6: =SUM('All_India_Index_Upto_April23 (1'!V373) -> 182.8 | C6: =B6/$B$8*100 -> 4.2619664
A7: Miscellaneous Services | B7: =SUM('All_India_Index_Upto_April23 (1'!W373:AC373) -> 1234.9 | C7: =B7/$B$8*100 -> 28.791588
A8: GRAND TOTAL | B8: =SUM(B2:B7) -> 4289.1 | C8: =SUM(C2:C7) -> 100

Sheet Y-O-Y Analysis
A1: Year | B1: Avg General Index | C1: YoY Growth %
A2: 2013 | B2: =ROUND(AVERAGEIFS('All_India_Index_Upto_April23 (1'!$AD:$AD,'All_India_Index_Upto_April23 (1'!$B:$B,A2,'All_India_Index_Upto_April23 (1'!$A:$A,"Rural+Urban"),2) -> 110.03 | N2: Reason for High Inflation in 2022
A3: 2014 | B3: =ROUND(AVERAGEIFS('All_India_Index_Upto_April23 (1'!$AD:$AD,'All_India_Index_Upto_April23 (1'!$B:$B,A3,'All_India_Index_Upto_April23 (1'!$A:$A,"Rural+Urban"),2) -> 117.35 | C3: =ROUND((B3-B2)/B2*100,2) -> 6.65 | N3: 1- Russia Ukraine War → Food & Oil prices spike
A4: 2015 | B4: =ROUND(AVERAGEIFS('All_India_Index_Upto_April23 (1'!$AD:$AD,'All_India_Index_Upto_April23 (1'!$B:$B,A4,'All_India_Index_Upto_April23 (1'!$A:$A,"Rural+Urban"),2) -> 123.11 | C4: =ROUND((B4-B3)/B3*100,2) -> 4.91 | N4: 2-High crude oil prices → Fuel inflation
A5: 2016 | B5: =ROUND(AVERAGEIFS('All_India_Index_Upto_April23 (1'!$AD:$AD,'All_India_Index_Upto_April23 (1'!$B:$B,A5,'All_India_Index_Upto_April23 (1'!$A:$A,"Rural+Urban"),2) -> 129.2 | C5: =ROUND((B5-B4)/B4*100,2) -> 4.95 | N5: 3-Post COVID supply chain disruption
A6: 2017 | B6: =ROUND(AVERAGEIFS('All_India_Index_Upto_April23 (1'!$AD:$AD,'All_India_Index_Upto_April23 (1'!$B:$B,A6,'All_India_Index_Upto_April23 (1'!$A:$A,"Rural+Urban"),2) -> 133.5 | C6: =ROUND((B6-B5)/B5*100,2) -> 3.33 | N6: 4-Weak Rupee → Expensive imports
A7: 2018 | B7: =ROUND(AVERAGEIFS('All_India_Index_Upto_April23 (1'!$AD:$AD,'All_India_Index_Upto_April23 (1'!$B:$B,A7,'All_India_Index_Upto_April23 (1'!$A:$A,"Rural+Urban"),2) -> 138.78 | C7: =ROUND((B7-B6)/B6*100,2) -> 3.96
A8: 2019 | B8: =ROUND(AVERAGEIFS('All_India_Index_Upto_April23 (1'!$AD:$AD,'All_India_Index_Upto_April23 (1'!$B:$B,A8,'All_India_Index_Upto_April23 (1'!$A:$A,"Rural+Urban"),2) -> 144.18 | C8: =ROUND((B8-B7)/B7*100,2) -> 3.89
A9: 2020 | B9: =ROUND(AVERAGEIFS('All_India_Index_Upto_April23 (1'!$AD:$AD,'All_India_Index_Upto_April23 (1'!$B:$B,A9,'All_India_Index_Upto_April23 (1'!$A:$A,"Rural+Urban"),2) -> 153.38 | C9: =ROUND((B9-B8)/B8*100,2) -> 6.38
A10: 2021 | B10: =ROUND(AVERAGEIFS('All_India_Index_Upto_April23 (1'!$AD:$AD,'All_India_Index_Upto_April23 (1'!$B:$B,A10,'All_India_Index_Upto_April23 (1'!$A:$A,"Rural+Urban"),2) -> 161.46 | C10: =ROUND((B10-B9)/B9*100,2) -> 5.27
A11: 2022 | B11: =ROUND(AVERAGEIFS('All_India_Index_Upto_April23 (1'!$AD:$AD,'All_India_Index_Upto_April23 (1'!$B:$B,A11,'All_India_Index_Upto_April23 (1'!$A:$A,"Rural+Urban"),2) -> 172.15 | C11: =ROUND((B11-B10)/B10*100,2) -> 6.62
A12: 2023 | B12: =ROUND(AVERAGEIFS('All_India_Index_Upto_April23 (1'!$AD:$AD,'All_India_Index_Upto_April23 (1'!$B:$B,A12,'All_India_Index_Upto_April23 (1'!$A:$A,"Rural+Urban"),2) -> 177.62 | C12: =ROUND((B12-B11)/B11*100,2) -> 3.18

Sheet Food Trend Analysis
A1: Month | B1: Year | C1: Food Index | D1: M o M % | F1: Sub Category | G1: 44713 | H1: 45047 | I1: Absolute Change
A2: June | B2: 2022 | C2: =AVERAGEIFS('Cleaned data'!$P:$P,'Cleaned data'!$A:$A,"Rural+Urban",'Cleaned data'!$C:$C,A2,'Cleaned data'!$B:$B,B2) -> 174.9 | D2: =ROUND((C3-C2)/C2*100,2) -> 0.06 | F2: Cereals and products | G2: =AVERAGEIFS('Cleaned data'!$D:$D,'Cleaned data'!$A:$A,"Rural+Urban",'Cleaned data'!$C:$C,"June",'Cleaned data'!$B:$B,2022) -> 155 | H2: =AVERAGEIFS('Cleaned data'!$D:$D,'Cleaned data'!$A:$A,"Rural+Urban",'Cleaned data'!$C:$C,"May",'Cleaned data'!$B:$B,2023) -> 173.7 | I2: =H2-G2 -> 18.7 | K2: max inflation | L2: =MAX(I2:I13) -> 30.9
A3: July | B3: 2022 | C3: =AVERAGEIFS('Cleaned data'!$P:$P,'Cleaned data'!$A:$A,"Rural+Urban",'Cleaned data'!$C:$C,A3,'Cleaned data'!$B:$B,B3) -> 175 | D3: =ROUND((C4-C3)/C3*100,2) -> 0.74 | F3: Meat and fish | G3: =AVERAGEIFS('Cleaned data'!$E:$E,'Cleaned data'!$A:$A,"Rural+Urban",'Cleaned data'!$C:$C,"June",'Cleaned data'!$B:$B,2022) -> 219.4 | H3: =AVERAGEIFS('Cleaned data'!$E:$E,'Cleaned data'!$A:$A,"Rural+Urban",'Cleaned data'!$C:$C,"May",'Cleaned data'!$B:$B,2023) -> 214.3 | I3: =H3-G3 -> -5.1 | K3: biggest contributor | L3: =INDEX(F2:F13,MATCH(MAX(I2:I13),I2:I13,0)) -> spices
A4: August | B4: 2022 | C4: =AVERAGEIFS('Cleaned data'!$P:$P,'Cleaned data'!$A:$A,"Rural+Urban",'Cleaned data'!$C:$C,A4,'Cleaned data'!$B:$B,B4) -> 176.3 | D4: =ROUND((C5-C4)/C4*100,2) -> 0.85 | F4: Eggs | G4: =AVERAGEIFS('Cleaned data'!$F:$F,'Cleaned data'!$A:$A,"Rural+Urban",'Cleaned data'!$C:$C,"June",'Cleaned data'!$B:$B,2022) -> 170.8 | H4: =AVERAGEIFS('Cleaned data'!$F:$F,'Cleaned data'!$A:$A,"Rural+Urban",'Cleaned data'!$C:$C,"May",'Cleaned data'!$B:$B,2023) -> 173.2 | I4: =H4-G4 -> 2.4
A5: September | B5: 2022 | C5: =AVERAGEIFS('Cleaned data'!$P:$P,'Cleaned data'!$A:$A,"Rural+Urban",'Cleaned data'!$C:$C,A5,'Cleaned data'!$B:$B,B5) -> 177.8 | D5: =ROUND((C6-C5)/C5*100,2) -> 1.01 | F5: Milk and products | G5: =AVERAGEIFS('Cleaned data'!$G:$G,'Cleaned data'!$A:$A,"Rural+Urban",'Cleaned data'!$C:$C,"June",'Cleaned data'!$B:$B,2022) -> 165.8 | H5: =AVERAGEIFS('Cleaned data'!$G:$G,'Cleaned data'!$A:$A,"Rural+Urban",'Cleaned data'!$C:$C,"May",'Cleaned data'!$B:$B,2023) -> 179.5 | I5: =H5-G5 -> 13.7
A6: October | B6: 2022 | C6: =AVERAGEIFS('Cleaned data'!$P:$P,'Cleaned data'!$A:$A,"Rural+Urban",'Cleaned data'!$C:$C,A6,'Cleaned data'!$B:$B,B6) -> 179.6 | D6: =ROUND((C7-C6)/C6*100,2) -> -0.72 | F6: Oils and fats | G6: =AVERAGEIFS('Cleaned data'!$H:$H,'Cleaned data'!$A:$A,"Rural+Urban",'Cleaned data'!$C:$C,"June",'Cleaned data'!$B:$B,2022) -> 200.9 | H6: =AVERAGEIFS('Cleaned data'!$H:$H,'Cleaned data'!$A:$A,"Rural+Urban",'Cleaned data'!$C:$C,"May",'Cleaned data'!$B:$B,2023) -> 170 | I6: =H6-G6 -> -30.9
A7: November | B7: 2022 | C7: =AVERAGEIFS('Cleaned data'!$P:$P,'Cleaned data'!$A:$A,"Rural+Urban",'Cleaned data'!$C:$C,A7,'Cleaned data'!$B:$B,B7) -> 178.3 | D7: =ROUND((C8-C7)/C7*100,2) -> -1.35 | F7: Fruits | G7: =AVERAGEIFS('Cleaned data'!$I:$I,'Cleaned data'!$A:$A,"Rural+Urban",'Cleaned data'!$C:$C,"June",'Cleaned data'!$B:$B,2022) -> 169.7 | H7: =AVERAGEIFS('Cleaned data'!$I:$I,'Cleaned data'!$A:$A,"Rural+Urban",'Cleaned data'!$C:$C,"May",'Cleaned data'!$B:$B,2023) -> 172.2 | I7: =H7-G7 -> 2.5
A8: December | B8: 2022 | C8: =AVERAGEIFS('Cleaned data'!$P:$P,'Cleaned data'!$A:$A,"Rural+Urban",'Cleaned data'!$C:$C,A8,'Cleaned data'!$B:$B,B8) -> 175.9 | D8: =ROUND((C9-C8)/C8*100,2) -> 0.45 | F8: Vegetables | G8: =AVERAGEIFS('Cleaned data'!$J:$J,'Cleaned data'!$A:$A,"Rural+Urban",'Cleaned data'!$C:$C,"June",'Cleaned data'!$B:$B,2022) -> 182.3 | H8: =AVERAGEIFS('Cleaned data'!$J:$J,'Cleaned data'!$A:$A,"Rural+Urban",'Cleaned data'!$C:$C,"May",'Cleaned data'!$B:$B,2023) -> 161 | I8: =H8-G8 -> -21.3
A9: January | B9: 2023 | C9: =AVERAGEIFS('Cleaned data'!$P:$P,'Cleaned data'!$A:$A,"Rural+Urban",'Cleaned data'!$C:$C,A9,'Cleaned data'!$B:$B,B9) -> 176.7 | D9: =ROUND((C10-C9)/C9*100,2) -> 0.17 | F9: Pulses and products | G9: =AVERAGEIFS('Cleaned data'!$K:$K,'Cleaned data'!$A:$A,"Rural+Urban",'Cleaned data'!$C:$C,"June",'Cleaned data'!$B:$B,2022) -> 164.3 | H9: =AVERAGEIFS('Cleaned data'!$K:$K,'Cleaned data'!$A:$A,"Rural+Urban",'Cleaned data'!$C:$C,"May",'Cleaned data'!$B:$B,2023) -> 175.6 | I9: =H9-G9 -> 11.3
A10: February | B10: 2023 | C10: =AVERAGEIFS('Cleaned data'!$P:$P,'Cleaned data'!$A:$A,"Rural+Urban",'Cleaned data'!$C:$C,A10,'Cleaned data'!$B:$B,B10) -> 177 | D10: =ROUND((C11-C10)/C10*100,2) -> 0 | F10: Sugar and Confectionery | G10: =AVERAGEIFS('Cleaned data'!$L:$L,'Cleaned data'!$A:$A,"Rural+Urban",'Cleaned data'!$C:$C,"June",'Cleaned data'!$B:$B,2022) -> 119.9 | H10: =AVERAGEIFS('Cleaned data'!$L:$L,'Cleaned data'!$A:$A,"Rural+Urban",'Cleaned data'!$C:$C,"May",'Cleaned data'!$B:$B,2023) -> 122.7 | I10: =H10-G10 -> 2.8
A11: March | B11: 2023 | C11: =AVERAGEIFS('Cleaned data'!$P:$P,'Cleaned data'!$A:$A,"Rural+Urban",'Cleaned data'!$C:$C,A11,'Cleaned data'!$B:$B,B11) -> 177 | D11: =ROUND((C12-C11)/C11*100,2) -> 0.51 | F11: spices | G11: =AVERAGEIFS('Cleaned data'!$M:$M,'Cleaned data'!$A:$A,"Rural+Urban",'Cleaned data'!$C:$C,"June",'Cleaned data'!$B:$B,2022) -> 187.1 | H11: =AVERAGEIFS('Cleaned data'!$M:$M,'Cleaned data'!$A:$A,"Rural+Urban",'Cleaned data'!$C:$C,"May",'Cleaned data'!$B:$B,2023) -> 218 | I11: =H11-G11 -> 30.9
A12: April | B12: 2023 | C12: =AVERAGEIFS('Cleaned data'!$P:$P,'Cleaned data'!$A:$A,"Rural+Urban",'Cleaned data'!$C:$C,A12,'Cleaned data'!$B:$B,B12) -> 177.9 | D12: =ROUND((C13-C12)/C12*100,2) -> 0.67 | F12: Non-alcoholic beverages | G12: =AVERAGEIFS('Cleaned data'!$N:$N,'Cleaned data'!$A:$A,"Rural+Urban",'Cleaned data'!$C:$C,"June",'Cleaned data'!$B:$B,2022) -> 167.9 | H12: =AVERAGEIFS('Cleaned data'!$N:$N,'Cleaned data'!$A:$A,"Rural+Urban",'Cleaned data'!$C:$C,"May",'Cleaned data'!$B:$B,2023) -> 173.4 | I12: =H12-G12 -> 5.5
A13: May | B13: 2023 | C13: =AVERAGEIFS('Cleaned data'!$P:$P,'Cleaned data'!$A:$A,"Rural+Urban",'Cleaned data'!$C:$C,A13,'Cleaned data'!$B:$B,B13) -> 179.1 | F13: Prepared meals, snacks, sweets | G13: =AVERAGEIFS('Cleaned data'!$O:$O,'Cleaned data'!$A:$A,"Rural+Urban",'Cleaned data'!$C:$C,"June",'Cleaned data'!$B:$B,2022) -> 183.9 | H13: =AVERAGEIFS('Cleaned data'!$O:$O,'Cleaned data'!$A:$A,"Rural+Urban",'Cleaned data'!$C:$C,"May",'Cleaned data'!$B:$B,2023) -> 194.2 | I13: =H13-G13 -> 10.3

Sheet COVID Impact Analysis
A1: Period | B1: Avg Food Index | C1: Avg Health Index | D1: Avg General Index | E1: Food % Change | F1: Health % Change | G1: General % Change
A2: Pre COVID (2017-Feb 2020) | B2: =AVERAGEIFS('Cleaned data'!$P:$P,'Cleaned data'!$A:$A,"Rural+Urban",'Cleaned data'!$B:$B,">="&2017,'Cleaned data'!$B:$B,"<="&2019) -> 140.10571 | C2: =AVERAGEIFS('Cleaned data'!$X:$X,'Cleaned data'!$A:$A,"Rural+Urban",'Cleaned data'!$B:$B,">="&2017,'Cleaned data'!$B:$B,"<="&2019) -> 138.05143 | D2: =AVERAGEIFS('Cleaned data'!$AD:$AD,'Cleaned data'!$A:$A,"Rural+Urban",'Cleaned data'!$B:$B,">="&2017,'Cleaned data'!$B:$B,"<="&2019) -> 138.66571
A3: COVID Onset (Mar-Dec 2020) | B3: =AVERAGEIFS('Cleaned data'!$P:$P,'Cleaned data'!$A:$A,"Rural+Urban",'Cleaned data'!$B:$B,2020) -> 156.25455 | C3: =AVERAGEIFS('Cleaned data'!$X:$X,'Cleaned data'!$A:$A,"Rural+Urban",'Cleaned data'!$B:$B,2020) -> 154.28182 | D3: =AVERAGEIFS('Cleaned data'!$AD:$AD,'Cleaned data'!$A:$A,"Rural+Urban",'Cleaned data'!$B:$B,2020) -> 153.38 | E3: =ROUND((B3-B2)/B2*100,2) -> 11.53 | F3: =ROUND((C3-C2)/C2*100,2) -> 11.76 | G3: =ROUND((D3-D2)/D2*100,2) -> 10.61
A4: Post COVID (2021-May 2023) | B4: =AVERAGEIFS('Cleaned data'!$P:$P,'Cleaned data'!$A:$A,"Rural+Urban",'Cleaned data'!$B:$B,">="&2021) -> 169.79655 | C4: =AVERAGEIFS('Cleaned data'!$X:$X,'Cleaned data'!$A:$A,"Rural+Urban",'Cleaned data'!$B:$B,">="&2021) -> 173.2069 | D4: =AVERAGEIFS('Cleaned data'!$AD:$AD,'Cleaned data'!$A:$A,"Rural+Urban",'Cleaned data'!$B:$B,">="&2021) -> 168.66897 | E4: =ROUND((B4-B2)/B2*100,2) -> 21.19 | F4: =ROUND((C4-C2)/C2*100,2) -> 25.47 | G4: =ROUND((D4-D2)/D2*100,2) -> 21.64

Sheet Oil Price Analysis
A1: Month | B1: Year | C1: Fuel & Light Index | D1: MoM Change % | F1: Category | G1: Correlation with Fuel
A2: January | B2: 2021 | C2: =AVERAGEIFS('Cleaned data'!$V:$V,'Cleaned data'!$A:$A,"Rural+Urban",'Cleaned data'!$C:$C,A2,'Cleaned data'!$B:$B,B2) -> 147.9 | D2: =ROUND((C3-C2)/C2*100,2) -> 3.04 | F2: Cereals and products | G2: =CORREL($C$2:$C$30,AVERAGEIFS('Cleaned data'!$D:$D,'Cleaned data'!$A:$A,"Rural+Urban",'Cleaned data'!$B:$B,$B$2:$B$30,'Cleaned data'!$C:$C,$A$2:$A$30)) -> 0.90866976
A3: February | B3: 2021 | C3: =AVERAGEIFS('Cleaned data'!$V:$V,'Cleaned data'!$A:$A,"Rural+Urban",'Cleaned data'!$C:$C,A3,'Cleaned data'!$B:$B,B3) -> 152.4 | D3: =ROUND((C4-C3)/C3*100,2) -> 2.03 | F3: Meat and fish | G3: =CORREL($C$2:$C$30,AVERAGEIFS('Cleaned data'!$E:$E,'Cleaned data'!$A:$A,"Rural+Urban",'Cleaned data'!$B:$B,$B$2:$B$30,'Cleaned data'!$C:$C,$A$2:$A$30)) -> 0.80888751
A4: March | B4: 2021 | C4: =AVERAGEIFS('Cleaned data'!$V:$V,'Cleaned data'!$A:$A,"Rural+Urban",'Cleaned data'!$C:$C,A4,'Cleaned data'!$B:$B,B4) -> 155.5 | D4: =ROUND((C5-C4)/C4*100,2) -> 0.06 | F4: Egg | G4: =CORREL($C$2:$C$30,AVERAGEIFS('Cleaned data'!$F:$F,'Cleaned data'!$A:$A,"Rural+Urban",'Cleaned data'!$B:$B,$B$2:$B$30,'Cleaned data'!$C:$C,$A$2:$A$30)) -> 0.24307343 | J4: Max Correl | K4: =MAX(G2:G20) -> 0.98708804
A5: April | B5: 2021 | C5: =AVERAGEIFS('Cleaned data'!$V:$V,'Cleaned data'!$A:$A,"Rural+Urban",'Cleaned data'!$C:$C,A5,'Cleaned data'!$B:$B,B5) -> 155.6 | D5: =ROUND((C6-C5)/C5*100,2) -> 2.44 | F5: Milk and products | G5: =CORREL($C$2:$C$30,AVERAGEIFS('Cleaned data'!G:$G,'Cleaned data'!$A:$A,"Rural+Urban",'Cleaned data'!$B:$B,$B$2:$B$30,'Cleaned data'!$C:$C,$A$2:$A$30)) -> 0.94294073 | J5: Strongest Category | K5: =INDEX(F2:F20,MATCH(MAX(G2:G20),G2:G20,0)) -> Footwear
A6: May | B6: 2021 | C6: =AVERAGEIFS('Cleaned data'!$V:$V,'Cleaned data'!$A:$A,"Rural+Urban",'Cleaned data'!$C:$C,A6,'Cleaned data'!$B:$B,B6) -> 159.4 | D6: =ROUND((C7-C6)/C6*100,2) -> 0.25 | F6: Oils and fats | G6: =CORREL($C$2:$C$30,AVERAGEIFS('Cleaned data'!$H:$H,'Cleaned data'!$A:$A,"Rural+Urban",'Cleaned data'!$B:$B,$B$2:$B$30,'Cleaned data'!$C:$C,$A$2:$A$30)) -> 0.48930201
A7: June | B7: 2021 | C7: =AVERAGEIFS('Cleaned data'!$V:$V,'Cleaned data'!$A:$A,"Rural+Urban",'Cleaned data'!$C:$C,A7,'Cleaned data'!$B:$B,B7) -> 159.8 | D7: =ROUND((C8-C7)/C7*100,2) -> 0.56 | F7: Fruits | G7: =CORREL($C$2:$C$30,AVERAGEIFS('Cleaned data'!$I:$I,'Cleaned data'!$A:$A,"Rural+Urban",'Cleaned data'!$B:$B,$B$2:$B$30,'Cleaned data'!$C:$C,$A$2:$A$30)) -> 0.63933553
A8: July | B8: 2021 | C8: =AVERAGEIFS('Cleaned data'!$V:$V,'Cleaned data'!$A:$A,"Rural+Urban",'Cleaned data'!$C:$C,A8,'Cleaned data'!$B:$B,B8) -> 160.7 | D8: =ROUND((C9-C8)/C8*100,2) -> 1.18 | F8: Vegetables | G8: =CORREL($C$2:$C$30,AVERAGEIFS('Cleaned data'!$J:$J,'Cleaned data'!$A:$A,"Rural+Urban",'Cleaned data'!$B:$B,$B$2:$B$30,'Cleaned data'!$C:$C,$A$2:$A$30)) -> 0.096863147
A9: August | B9: 2021 | C9: =AVERAGEIFS('Cleaned data'!$V:$V,'Cleaned data'!$A:$A,"Rural+Urban",'Cleaned data'!$C:$C,A9,'Cleaned data'!$B:$B,B9) -> 162.6 | D9: =ROUND((C10-C9)/C9*100,2) -> 0 | F9: Pulses and products | G9: =CORREL($C$2:$C$30,AVERAGEIFS('Cleaned data'!$K:$K,'Cleaned data'!$A:$A,"Rural+Urban",'Cleaned data'!$B:$B,$B$2:$B$30,'Cleaned data'!$C:$C,$A$2:$A$30)) -> 0.8498993
A10: September | B10: 2021 | C10: =AVERAGEIFS('Cleaned data'!$V:$V,'Cleaned data'!$A:$A,"Rural+Urban",'Cleaned data'!$C:$C,A10,'Cleaned data'!$B:$B,B10) -> 162.6 | D10: =ROUND((C11-C10)/C10*100,2) -> 0.98 | F10: Sugar and Confectionery | G10: =CORREL($C$2:$C$30,AVERAGEIFS('Cleaned data'!$L:$L,'Cleaned data'!$A:$A,"Rural+Urban",'Cleaned data'!$B:$B,$B$2:$B$30,'Cleaned data'!$C:$C,$A$2:$A$30)) -> 0.7707871
A11: October | B11: 2021 | C11: =AVERAGEIFS('Cleaned data'!$V:$V,'Cleaned data'!$A:$A,"Rural+Urban",'Cleaned data'!$C:$C,A11,'Cleaned data'!$B:$B,B11) -> 164.2 | D11: =ROUND((C12-C11)/C11*100,2) -> -0.18 | F11: Spices | G11: =CORREL($C$2:$C$30,AVERAGEIFS('Cleaned data'!$M:$M,'Cleaned data'!$A:$A,"Rural+Urban",'Cleaned data'!$B:$B,$B$2:$B$30,'Cleaned data'!$C:$C,$A$2:$A$30)) -> 0.93896615
A12: November | B12: 2021 | C12: =AVERAGEIFS('Cleaned data'!$V:$V,'Cleaned data'!$A:$A,"Rural+Urban",'Cleaned data'!$C:$C,A12,'Cleaned data'!$B:$B,B12) -> 163.9 | D12: =ROUND((C13-C12)/C12*100,2) -> 0.12 | F12: Non-alcoholic beverages | G12: =CORREL($C$2:$C$30,AVERAGEIFS('Cleaned data'!$N:$N,'Cleaned data'!$A:$A,"Rural+Urban",'Cleaned data'!$B:$B,$B$2:$B$30,'Cleaned data'!$C:$C,$A$2:$A$30)) -> 0.97878577
A13: December | B13: 2021 | C13: =AVERAGEIFS('Cleaned data'!$V:$V,'Cleaned data'!$A:$A,"Rural+Urban",'Cleaned data'!$C:$C,A13,'Cleaned data'!$B:$B,B13) -> 164.1 | D13: =ROUND((C14-C13)/C13*100,2) -> 0.06 | F13: Prepared meals | G13: =CORREL($C$2:$C$30,AVERAGEIFS('Cleaned data'!$O:$O,'Cleaned data'!$A:$A,"Rural+Urban",'Cleaned data'!$B:$B,$B$2:$B$30,'Cleaned data'!$C:$C,$A$2:$A$30)) -> 0.98227979
A14: January | B14: 2022 | C14: =AVERAGEIFS('Cleaned data'!$V:$V,'Cleaned data'!$A:$A,"Rural+Urban",'Cleaned data'!$C:$C,A14,'Cleaned data'!$B:$B,B14) -> 164.2 | D14: =ROUND((C15-C14)/C14*100,2) -> 0.91 | F14: Pan tobacco & intoxicants | G14: =CORREL($C$2:$C$30,AVERAGEIFS('Cleaned data'!$Q:$Q,'Cleaned data'!$A:$A,"Rural+Urban",'Cleaned data'!$B:$B,$B$2:$B$30,'Cleaned data'!$C:$C,$A$2:$A$30)) -> 0.93979244
A15: February | B15: 2022 | C15: =AVERAGEIFS('Cleaned data'!$V:$V,'Cleaned data'!$A:$A,"Rural+Urban",'Cleaned data'!$C:$C,A15,'Cleaned data'!$B:$B,B15) -> 165.7 | D15: =ROUND((C16-C15)/C15*100,2) -> 0.91 | F15: Clothing | G15: =CORREL($C$2:$C$30,AVERAGEIFS('Cleaned data'!$R:$R,'Cleaned data'!$A:$A,"Rural+Urban",'Cleaned data'!$B:$B,$B$2:$B$30,'Cleaned data'!$C:$C,$A$2:$A$30)) -> 0.98511498
A16: March | B16: 2022 | C16: =AVERAGEIFS('Cleaned data'!$V:$V,'Cleaned data'!$A:$A,"Rural+Urban",'Cleaned data'!$C:$C,A16,'Cleaned data'!$B:$B,B16) -> 167.2 | D16: =ROUND((C17-C16)/C16*100,2) -> 2.99 | F16: Footwear | G16: =CORREL($C$2:$C$30,AVERAGEIFS('Cleaned data'!$S:$S,'Cleaned data'!$A:$A,"Rural+Urban",'Cleaned data'!$B:$B,$B$2:$B$30,'Cleaned data'!$C:$C,$A$2:$A$30)) -> 0.98708804
A17: April | B17: 2022 | C17: =AVERAGEIFS('Cleaned data'!$V:$V,'Cleaned data'!$A:$A,"Rural+Urban",'Cleaned data'!$C:$C,A17,'Cleaned data'!$B:$B,B17) -> 172.2 | D17: =ROUND((C18-C17)/C17*100,2) -> 1.39 | F17: Health | G17: =CORREL($C$2:$C$30,AVERAGEIFS('Cleaned data'!$X:$X,'Cleaned data'!$A:$A,"Rural+Urban",'Cleaned data'!$B:$B,$B$2:$B$30,'Cleaned data'!$C:$C,$A$2:$A$30)) -> 0.96917346
A18: May | B18: 2022 | C18: =AVERAGEIFS('Cleaned data'!$V:$V,'Cleaned data'!$A:$A,"Rural+Urban",'Cleaned data'!$C:$C,A18,'Cleaned data'!$B:$B,B18) -> 174.6 | D18: =ROUND((C19-C18)/C18*100,2) -> 0.8 | F18: Transport and communication | G18: =CORREL($C$2:$C$30,AVERAGEIFS('Cleaned data'!$Y:$Y,'Cleaned data'!$A:$A,"Rural+Urban",'Cleaned data'!$B:$B,$B$2:$B$30,'Cleaned data'!$C:$C,$A$2:$A$30)) -> 0.96707996
A19: June | B19: 2022 | C19: =AVERAGEIFS('Cleaned data'!$V:$V,'Cleaned data'!$A:$A,"Rural+Urban",'Cleaned data'!$C:$C,A19,'Cleaned data'!$B:$B,B19) -> 176 | D19: =ROUND((C20-C19)/C19*100,2) -> 2.05 | F19: Education | G19: =CORREL($C$2:$C$30,AVERAGEIFS('Cleaned data'!$Z:$Z,'Cleaned data'!$A:$A,"Rural+Urban",'Cleaned data'!$B:$B,$B$2:$B$30,'Cleaned data'!$C:$C,$A$2:$A$30)) -> 0.98447621
A20: July | B20: 2022 | C20: =AVERAGEIFS('Cleaned data'!$V:$V,'Cleaned data'!$A:$A,"Rural+Urban",'Cleaned data'!$C:$C,A20,'Cleaned data'!$B:$B,B20) -> 179.6 | D20: =ROUND((C21-C20)/C20*100,2) -> -0.45 | F20: Miscellaneous | G20: =CORREL($C$2:$C$30,AVERAGEIFS('Cleaned data'!$AC:$AC,'Cleaned data'!$A:$A,"Rural+Urban",'Cleaned data'!$B:$B,$B$2:$B$30,'Cleaned data'!$C:$C,$A$2:$A$30)) -> 0.98253256
A21: August | B21: 2022 | C21: =AVERAGEIFS('Cleaned data'!$V:$V,'Cleaned data'!$A:$A,"Rural+Urban",'Cleaned data'!$C:$C,A21,'Cleaned data'!$B:$B,B21) -> 178.8 | D21: =ROUND((C22-C21)/C21*100,2) -> 0.39
A22: September | B22: 2022 | C22: =AVERAGEIFS('Cleaned data'!$V:$V,'Cleaned data'!$A:$A,"Rural+Urban",'Cleaned data'!$C:$C,A22,'Cleaned data'!$B:$B,B22) -> 179.5 | D22: =ROUND((C23-C22)/C22*100,2) -> 0.56
A23: October | B23: 2022 | C23: =AVERAGEIFS('Cleaned data'!$V:$V,'Cleaned data'!$A:$A,"Rural+Urban",'Cleaned data'!$C:$C,A23,'Cleaned data'!$B:$B,B23) -> 180.5 | D23: =ROUND((C24-C23)/C23*100,2) -> 0.44
A24: November | B24: 2022 | C24: =AVERAGEIFS('Cleaned data'!$V:$V,'Cleaned data'!$A:$A,"Rural+Urban",'Cleaned data'!$C:$C,A24,'Cleaned data'!$B:$B,B24) -> 181.3 | D24: =ROUND((C25-C24)/C24*100,2) -> 0.39
A25: December | B25: 2022 | C25: =AVERAGEIFS('Cleaned data'!$V:$V,'Cleaned data'!$A:$A,"Rural+Urban",'Cleaned data'!$C:$C,A25,'Cleaned data'!$B:$B,B25) -> 182 | D25: =ROUND((C26-C25)/C25*100,2) -> 0
A26: January | B26: 2023 | C26: =AVERAGEIFS('Cleaned data'!$V:$V,'Cleaned data'!$A:$A,"Rural+Urban",'Cleaned data'!$C:$C,A26,'Cleaned data'!$B:$B,B26) -> 182 | D26: =ROUND((C27-C26)/C26*100,2) -> 0.05
A27: February | B27: 2023 | C27: =AVERAGEIFS('Cleaned data'!$V:$V,'Cleaned data'!$A:$A,"Rural+Urban",'Cleaned data'!$C:$C,A27,'Cleaned data'!$B:$B,B27) -> 182.1 | D27: =ROUND((C28-C27)/C27*100,2) -> -0.11
A28: March | B28: 2023 | C28: =AVERAGEIFS('Cleaned data'!$V:$V,'Cleaned data'!$A:$A,"Rural+Urban",'Cleaned data'!$C:$C,A28,'Cleaned data'!$B:$B,B28) -> 181.9 | D28: =ROUND((C29-C28)/C28*100,2) -> -0.11
A29: April | B29: 2023 | C29: =AVERAGEIFS('Cleaned data'!$V:$V,'Cleaned data'!$A:$A,"Rural+Urban",'Cleaned data'!$C:$C,A29,'Cleaned data'!$B:$B,B29) -> 181.7 | D29: =ROUND((C30-C29)/C29*100,2) -> 0.61
A30: May | B30: 2023 | C30: =AVERAGEIFS('Cleaned data'!$V:$V,'Cleaned data'!$A:$A,"Rural+Urban",'Cleaned data'!$C:$C,A30,'Cleaned data'!$B:$B,B30) -> 182.8
